Error while loading conda entry point: anaconda-cloud-auth (cannot import name 'PyJWKClient' from 'jwt' (/opt/anaconda3/lib/python3.12/site-packages/jwt/__init__.py))
Error while loading conda entry point: anaconda-cloud-auth (cannot import name 'PyJWKClient' from 'jwt' (/opt/anaconda3/lib/python3.12/site-packages/jwt/__init__.py))
Error while loading conda entry point: anaconda-cloud-auth (cannot import name 'PyJWKClient' from 'jwt' (/opt/anaconda3/lib/python3.12/site-packages/jwt/__init__.py))
Error while loading conda entry point: anaconda-cloud-auth (cannot import name 'PyJWKClient' from 'jwt' (/opt/anaconda3/lib/python3.12/site-packages/jwt/__init__.py))
INFO:     Started server process [4980]
INFO:     Waiting for application startup.
INFO:     Application startup complete.
INFO:     Uvicorn running on http://127.0.0.1:8000 (Press CTRL+C to quit)
ERROR:    Exception in ASGI application
Traceback (most recent call last):
  File "/opt/anaconda3/lib/python3.12/site-packages/sqlalchemy/engine/base.py", line 1967, in _exec_single_context
    self.dialect.do_execute(
  File "/opt/anaconda3/lib/python3.12/site-packages/sqlalchemy/engine/default.py", line 941, in do_execute
    cursor.execute(statement, parameters)
sqlite3.OperationalError: attempt to write a readonly database

The above exception was the direct cause of the following exception:

Traceback (most recent call last):
  File "/opt/anaconda3/lib/python3.12/site-packages/uvicorn/protocols/http/httptools_impl.py", line 409, in run_asgi
    result = await app(  # type: ignore[func-returns-value]
             ^^^^^^^^^^^^^^^^^^^^^^^^^^^^^^^^^^^^^^^^^^^^^^
  File "/opt/anaconda3/lib/python3.12/site-packages/uvicorn/middleware/proxy_headers.py", line 60, in __call__
    return await self.app(scope, receive, send)
           ^^^^^^^^^^^^^^^^^^^^^^^^^^^^^^^^^^^^
  File "/opt/anaconda3/lib/python3.12/site-packages/fastapi/applications.py", line 1054, in __call__
    await super().__call__(scope, receive, send)
  File "/opt/anaconda3/lib/python3.12/site-packages/starlette/applications.py", line 112, in __call__
    await self.middleware_stack(scope, receive, send)
  File "/opt/anaconda3/lib/python3.12/site-packages/starlette/middleware/errors.py", line 187, in __call__
    raise exc
  File "/opt/anaconda3/lib/python3.12/site-packages/starlette/middleware/errors.py", line 165, in __call__
    await self.app(scope, receive, _send)
  File "/opt/anaconda3/lib/python3.12/site-packages/starlette/middleware/exceptions.py", line 62, in __call__
    await wrap_app_handling_exceptions(self.app, conn)(scope, receive, send)
  File "/opt/anaconda3/lib/python3.12/site-packages/starlette/_exception_handler.py", line 53, in wrapped_app
    raise exc
  File "/opt/anaconda3/lib/python3.12/site-packages/starlette/_exception_handler.py", line 42, in wrapped_app
    await app(scope, receive, sender)
  File "/opt/anaconda3/lib/python3.12/site-packages/starlette/routing.py", line 714, in __call__
    await self.middleware_stack(scope, receive, send)
  File "/opt/anaconda3/lib/python3.12/site-packages/starlette/routing.py", line 734, in app
    await route.handle(scope, receive, send)
  File "/opt/anaconda3/lib/python3.12/site-packages/starlette/routing.py", line 288, in handle
    await self.app(scope, receive, send)
  File "/opt/anaconda3/lib/python3.12/site-packages/starlette/routing.py", line 76, in app
    await wrap_app_handling_exceptions(app, request)(scope, receive, send)
  File "/opt/anaconda3/lib/python3.12/site-packages/starlette/_exception_handler.py", line 53, in wrapped_app
    raise exc
  File "/opt/anaconda3/lib/python3.12/site-packages/starlette/_exception_handler.py", line 42, in wrapped_app
    await app(scope, receive, sender)
  File "/opt/anaconda3/lib/python3.12/site-packages/starlette/routing.py", line 73, in app
    response = await f(request)
               ^^^^^^^^^^^^^^^^
  File "/opt/anaconda3/lib/python3.12/site-packages/fastapi/routing.py", line 301, in app
    raw_response = await run_endpoint_function(
                   ^^^^^^^^^^^^^^^^^^^^^^^^^^^^
  File "/opt/anaconda3/lib/python3.12/site-packages/fastapi/routing.py", line 214, in run_endpoint_function
    return await run_in_threadpool(dependant.call, **values)
           ^^^^^^^^^^^^^^^^^^^^^^^^^^^^^^^^^^^^^^^^^^^^^^^^^
  File "/opt/anaconda3/lib/python3.12/site-packages/starlette/concurrency.py", line 37, in run_in_threadpool
    return await anyio.to_thread.run_sync(func)
           ^^^^^^^^^^^^^^^^^^^^^^^^^^^^^^^^^^^^
  File "/opt/anaconda3/lib/python3.12/site-packages/anyio/to_thread.py", line 56, in run_sync
    return await get_async_backend().run_sync_in_worker_thread(
           ^^^^^^^^^^^^^^^^^^^^^^^^^^^^^^^^^^^^^^^^^^^^^^^^^^^^
  File "/opt/anaconda3/lib/python3.12/site-packages/anyio/_backends/_asyncio.py", line 2134, in run_sync_in_worker_thread
    return await future
           ^^^^^^^^^^^^
  File "/opt/anaconda3/lib/python3.12/site-packages/anyio/_backends/_asyncio.py", line 851, in run
    result = context.run(func, *args)
             ^^^^^^^^^^^^^^^^^^^^^^^^
  File "/Users/francoisreeves/benchHUB/benchHUB/api.py", line 64, in submit_result
    db.commit()
  File "/opt/anaconda3/lib/python3.12/site-packages/sqlalchemy/orm/session.py", line 2028, in commit
    trans.commit(_to_root=True)
  File "<string>", line 2, in commit
  File "/opt/anaconda3/lib/python3.12/site-packages/sqlalchemy/orm/state_changes.py", line 139, in _go
    ret_value = fn(self, *arg, **kw)
                ^^^^^^^^^^^^^^^^^^^^
  File "/opt/anaconda3/lib/python3.12/site-packages/sqlalchemy/orm/session.py", line 1313, in commit
    self._prepare_impl()
  File "<string>", line 2, in _prepare_impl
  File "/opt/anaconda3/lib/python3.12/site-packages/sqlalchemy/orm/state_changes.py", line 139, in _go
    ret_value = fn(self, *arg, **kw)
                ^^^^^^^^^^^^^^^^^^^^
  File "/opt/anaconda3/lib/python3.12/site-packages/sqlalchemy/orm/session.py", line 1288, in _prepare_impl
    self.session.flush()
  File "/opt/anaconda3/lib/python3.12/site-packages/sqlalchemy/orm/session.py", line 4352, in flush
    self._flush(objects)
  File "/opt/anaconda3/lib/python3.12/site-packages/sqlalchemy/orm/session.py", line 4487, in _flush
    with util.safe_reraise():
  File "/opt/anaconda3/lib/python3.12/site-packages/sqlalchemy/util/langhelpers.py", line 146, in __exit__
    raise exc_value.with_traceback(exc_tb)
  File "/opt/anaconda3/lib/python3.12/site-packages/sqlalchemy/orm/session.py", line 4448, in _flush
    flush_context.execute()
  File "/opt/anaconda3/lib/python3.12/site-packages/sqlalchemy/orm/unitofwork.py", line 466, in execute
    rec.execute(self)
  File "/opt/anaconda3/lib/python3.12/site-packages/sqlalchemy/orm/unitofwork.py", line 642, in execute
    util.preloaded.orm_persistence.save_obj(
  File "/opt/anaconda3/lib/python3.12/site-packages/sqlalchemy/orm/persistence.py", line 93, in save_obj
    _emit_insert_statements(
  File "/opt/anaconda3/lib/python3.12/site-packages/sqlalchemy/orm/persistence.py", line 1233, in _emit_insert_statements
    result = connection.execute(
             ^^^^^^^^^^^^^^^^^^^
  File "/opt/anaconda3/lib/python3.12/site-packages/sqlalchemy/engine/base.py", line 1418, in execute
    return meth(
           ^^^^^
  File "/opt/anaconda3/lib/python3.12/site-packages/sqlalchemy/sql/elements.py", line 515, in _execute_on_connection
    return connection._execute_clauseelement(
           ^^^^^^^^^^^^^^^^^^^^^^^^^^^^^^^^^^
  File "/opt/anaconda3/lib/python3.12/site-packages/sqlalchemy/engine/base.py", line 1640, in _execute_clauseelement
    ret = self._execute_context(
          ^^^^^^^^^^^^^^^^^^^^^^
  File "/opt/anaconda3/lib/python3.12/site-packages/sqlalchemy/engine/base.py", line 1846, in _execute_context
    return self._exec_single_context(
           ^^^^^^^^^^^^^^^^^^^^^^^^^^
  File "/opt/anaconda3/lib/python3.12/site-packages/sqlalchemy/engine/base.py", line 1986, in _exec_single_context
    self._handle_dbapi_exception(
  File "/opt/anaconda3/lib/python3.12/site-packages/sqlalchemy/engine/base.py", line 2355, in _handle_dbapi_exception
    raise sqlalchemy_exception.with_traceback(exc_info[2]) from e
  File "/opt/anaconda3/lib/python3.12/site-packages/sqlalchemy/engine/base.py", line 1967, in _exec_single_context
    self.dialect.do_execute(
  File "/opt/anaconda3/lib/python3.12/site-packages/sqlalchemy/engine/default.py", line 941, in do_execute
    cursor.execute(statement, parameters)
sqlalchemy.exc.OperationalError: (sqlite3.OperationalError) attempt to write a readonly database
[SQL: INSERT INTO results (system_info, cpu, memory, gpu, disk, ml, plot, reference_index) VALUES (?, ?, ?, ?, ?, ?, ?, ?)]
[parameters: ('{"os": "Darwin", "os_version": "Darwin Kernel Version 24.4.0: Fri Apr 11 18:32:50 PDT 2025; root:xnu-11417.101.15~117/RELEASE_ARM64_T6041", "architec ... (218 characters truncated) ... 46.8}, "gpus": "NVIDIA GPU not found or pynvml failed.", "torch_gpus": {"backend": "MPS", "device_count": 1, "device_names": ["Apple M-series GPU"]}}', '{"floating_point_operations": 0.0003879070281982422, "parallel_processing": 2.6258091926574707}', '{"allocation": 0.00021386146545410156}', '{"tensor_operations": 0.00019097328186035156, "tiny_training_loop": 0.0025882720947265625}', '{"write_time": 0.004677772521972656, "read_time": 0.0008208751678466797}', '{"timings": {"create_dataset": 0.0028870105743408203, "run_grid_search": 14.688884019851685}, "best_params": {"max_depth": 20, "n_estimators": 100}, "best_score": 0.9180000755719488}', '{"generate_scatter_plot": 0.0026700496673583984, "animate_sine_wave": 1.0081942081451416, "render_large_image": 0.4666769504547119}', 4060.8935942306507)]
(Background on this error at: https://sqlalche.me/e/20/e3q8)
/var/folders/3s/bnm4rg9917199zhf1bh2fd7w0000gn/T/tmp19n_bwv9: line 3:  4980 Killed: 9               python -m uvicorn benchHUB.api:app --host 127.0.0.1 --port 8000

ERROR conda.cli.main_run:execute(125): `conda run python -m uvicorn benchHUB.api:app --host 127.0.0.1 --port 8000` failed. (See above for error)
